<!DOCTYPE html>
<html lang="en">
<head>
    <meta charset="UTF-8">
    <meta name="viewport" content="width=device-width, initial-scale=1.0">
    <title>Async</title>
</head>
<body>
    <p>hello world</p>
</body>
<script>
    const {log} = console;
    //Async(异步) sync(同步) es8 - es2017,异步处理机制(Promise)



    //async什么时候回走到catch:两种情况 -> 1.async里边的代码报错 2.在异步的时候出错了
    // async function abc() {//没有办法手动的决定状态,状态默认是一个成功
    //     throw new Error('我是abc的错误');
    //     return ['abc'];//async通过return 向then里边传递成功的数据
    // };
    // const some =  async () => {
    //     throw new Error('我是some的错误');//promise里边的错误虽然会报红，但是不会影响代码的运行
    //     return {some: 'some'};
    // };
    // console.log( abc(), some() );
    //如果async函数里边什么都没有写，那么执行完成之后，返回的promise状态为resolved(成功)
    // abc()
    //     .then( data => {
    //         log( 'abc:', data )
    //     } )
    //     .catch( err => {
    //         log('abc里边的err:', err)
    //     } );
    // some()
    //     .then( data => {
    //         log('some:', data)
    //     } )
    //     .catch( err => {
    //         log('some里的err:', err);
    //     } )

    //在异步的时候出错了 async里边的另一个关键字: await[等待] + 异步操作(Promise)

    //await 后边的promise的状态会决定 async的状态
    // const add = async () => {
    //     let result = await new Promise( (resolve, reject) => {//等待Promise的结果，如果promise的状态是rejected(失败),async就会走到catch
    //         console.log('我是add内部的promise');
    //         reject(123)
    //     } );
    //     //当await等待的promise失败了，那么async函数会立即打断执行剩下的代码，直接走到catch
    //     log(result);//await会返回 等待的promise的成功结果

    // };
    // //一般写async函数的时候不会写then只写catch
    // add()
    //     .catch( err => {
    //         log('err:', err)
    //     } );

    //await等待异步操作: async本身是同步的,把异步代码写在async里边
    //await 会阻塞后边的代码执行，阻塞到Promise的状态改变为成功或者失败之后才会去执行后边的代码

    //在async里边代码完全会按照我们书写的顺序进行运行

    //一定要await一个promise，因为我们可以在自己写的promise里边主动的决定什么时候成功，什么时候失败
    //为什么要用Promise，因为要进行异步操作,根据异步操作的结果来做后边的事情。

    // const abc = async () => {
    //     //过了一秒钟之后，小明promise的结果才出来
    //     let result = await new Promise( (resolve, reject) => {//小明
    //         setTimeout( () => { reject('失败了') }, 1000 );//异步
    //     } ).catch( err => {//如果我们主动的捕获了Promise的错误，那么错误就不会传递给async，而且后边的代码还能正常运行
    //         console.log('我是promise的错误', err)
    //     } );

    //     log(result);//同步的 如果result是undefined那么表明Promise的状态失败了
    //     //更新页面内容

    // };
    // abc();


    // const some = async () => {
    //     let result = await new Promise( res => {
    //         let something = setTimeout( () => {
    //             console.log('我是setTimeout')
    //         }, 1000 );
    //         res(something)//1
    //     } )
    //    //如果我们等待的不是promise，则被等待的东西会被浏览器写到一个promise里边,而且被浏览器创建的这个promise的状态一定是成功
    //     return result;
    // };
    // some()
    //     .then(data => {
    //         console.log(data)
    //     })
    //     .catch( err => {
    //         console.log(err)
    //     } )

    // setTimeout( () => {
    //     console.log(123)
    // }, 1000 )
    // console.log(456)

    // new Promise( res => {
    //     setTimeout( () => {
    //         res( {nickname: '小明'} )
    //     }, 1000 )
    // } )
    //     .then( data => {
    //         console.log(data)
    //     } )
    //     .catch(err => {
    //         console.log(err)
    //     })  

    // let abb = '123';
    // p.innerHTml = add;


    //await可以await无数个promise，但是每个promise前边都要写一个await
    //当async里边有多个promise的时候，只要有一个promise的状态失败了，那么就失败了

    const fn = async () => {

        let a = new Promise( (res, rej) => {
            setTimeout( () => {
                res( {nickname: '小明'} );
            }, 1000 )
        } ).catch( err => { console.log(err) } );

        let b = new Promise( (res, rej) => {
            setTimeout( () => {
                res( {nickname: '小红'} );
            }, 1000 )
        } ).catch( err => { console.log(err) } );

        let c = new Promise( (res, rej) => {
            setTimeout( () => {
                rej( {nickname: '小刚'} );
            }, 1000 )
        } ).catch( err => { console.log(err) } );

        let result4 = await Promise.all([a, b, c]);

        console.log(result4);

    }
    fn();

    //同理可得， 易证
    // let a = new Promise( res => {
    //     setTimeout( () => { res( {nickname: '小刚'} ) }, 1000 );
    // } );

    // let b = new Promise( res => {
    //     setTimeout( () => { res( {nickname: '小明'} ) }, 1000 );
    // } );
    
    // let c = new Promise( (res, rej) => {
    //     setTimeout( () => { rej( {nickname: '小红'} ) }, 1000 );
    // } ).catch( err => {console.log('err:', err)} )

    // Promise.all( [a, b, c] )
    //     .then( data => {
    //         log(data)
    //     } )
    //     .catch( err => {
    //         log(err)
    //     } );



        
//在工作中，凡是ajax请求全都用async套起来 -> 以同步代码的方式去书写，然后代码还能从上到下按顺序执行
const some = async () => {

let result = await request( {
    url: 'http://localhost:3000/log',
    data: {
        username: 'xiaoming',
        passworld: '132'
    }
} );

log(result);
result += 'hello';
console.log(result);

};
// some();

//同步队列   异步队列( 1微[promise, async]， 2宏[定/延时器] )
//async a   创造async a  执行 顺序问题 -> 同步代码和异步代码的理解
async function a() {
console.log(1);
await new Promise(resolve => resolve());//P2 等待P2的resolve
console.log(2);
}
new Promise( res => {//P1 
console.log(3)
res()
}).then( () => {//P1的then
console.log(4)
new Promise( resolve => resolve() ).then( () => {console.log(5)} )//P3的then
})

setTimeout( () => {
console.log(6)
}, 0 )
a()
console.log(7)
//3 1 7  4  2 5 6




</script>
</html>